[2025-07-13 11:20:27 -0400] [86688] [INFO] Starting gunicorn 23.0.0
Traceback (most recent call last):
  File "/Users/abdulbaribest/Desktop/Carrer Star/CareerStar/backend/venv/bin/gunicorn", line 10, in <module>
    sys.exit(run())
             ~~~^^
  File "/Users/abdulbaribest/Desktop/Carrer Star/CareerStar/backend/venv/lib/python3.13/site-packages/gunicorn/app/wsgiapp.py", line 66, in run
    WSGIApplication("%(prog)s [OPTIONS] [APP_MODULE]", prog=prog).run()
    ~~~~~~~~~~~~~~~~~~~~~~~~~~~~~~~~~~~~~~~~~~~~~~~~~~~~~~~~~~~~~~~~~^^
  File "/Users/abdulbaribest/Desktop/Carrer Star/CareerStar/backend/venv/lib/python3.13/site-packages/gunicorn/app/base.py", line 235, in run
    super().run()
    ~~~~~~~~~~~^^
  File "/Users/abdulbaribest/Desktop/Carrer Star/CareerStar/backend/venv/lib/python3.13/site-packages/gunicorn/app/base.py", line 71, in run
    Arbiter(self).run()
    ~~~~~~~~~~~~~~~~~^^
  File "/Users/abdulbaribest/Desktop/Carrer Star/CareerStar/backend/venv/lib/python3.13/site-packages/gunicorn/arbiter.py", line 197, in run
    self.start()
    ~~~~~~~~~~^^
  File "/Users/abdulbaribest/Desktop/Carrer Star/CareerStar/backend/venv/lib/python3.13/site-packages/gunicorn/arbiter.py", line 154, in start
    self.LISTENERS = sock.create_sockets(self.cfg, self.log, fds)
                     ~~~~~~~~~~~~~~~~~~~^^^^^^^^^^^^^^^^^^^^^^^^^
  File "/Users/abdulbaribest/Desktop/Carrer Star/CareerStar/backend/venv/lib/python3.13/site-packages/gunicorn/sock.py", line 162, in create_sockets
    raise ValueError('certfile "%s" does not exist' % conf.certfile)
ValueError: certfile "/home/ubuntu/CareerStar/backend/cert.pem" does not exist
